Workbook

Sheet Output
B2: 10 LOWER SPADINA — PURPOSE-BUILT RENTAL SCENARIO — RENTAL COMP SUMMARY (Condos view)
B3: Building | C3: First Occupancy | D3: Avg.Lease Date | E3: Vacancy | F3: Transaction Count | G3: Avg Suite Size | H3: Adj. Avg. Rent | I3: Avg. Net Rent PSF
B5: Lower Spadina / CityPlace Waterfront
B6: Concord Canada House | C6: ='Building Summary'!E4 -> 2025 | D6: =IFERROR(AVERAGEIFS('RD Condos'!$J:$J,'RD Condos'!$K:$K,$B6,'RD Condos'!$A:$A,1),"") -> 45948.757 | F6: ='Building Summary'!J4 -> 284 | G6: ='Building Summary'!K4 -> 629.26056 | H6: =IFERROR(AVERAGEIFS('RD Condos'!$D:$D,'RD Condos'!$K:$K,$B6,'RD Condos'!$A:$A,1),"") -> 2649.8063 | I6: =IFERROR(AVERAGEIFS('RD Condos'!$F:$F,'RD Condos'!$K:$K,$B6,'RD Condos'!$A:$A,1),"") -> 4.2772544
B7: Nobu Residences | C7: ='Building Summary'!E5 -> 2024 | D7: =IFERROR(AVERAGEIFS('RD Condos'!$J:$J,'RD Condos'!$K:$K,$B7,'RD Condos'!$A:$A,1),"") -> 45938.78 | F7: ='Building Summary'!J5 -> 209 | G7: ='Building Summary'!K5 -> 720.84211 | H7: =IFERROR(AVERAGEIFS('RD Condos'!$D:$D,'RD Condos'!$K:$K,$B7,'RD Condos'!$A:$A,1),"") -> 3099.9617 | I7: =IFERROR(AVERAGEIFS('RD Condos'!$F:$F,'RD Condos'!$K:$K,$B7,'RD Condos'!$A:$A,1),"") -> 4.3365306
B8: The Well | C8: ='Building Summary'!E6 -> 2024 | D8: =IFERROR(AVERAGEIFS('RD Condos'!$J:$J,'RD Condos'!$K:$K,$B8,'RD Condos'!$A:$A,1),"") -> 45983.375 | F8: ='Building Summary'!J6 -> 56 | G8: ='Building Summary'!K6 -> 948.60714 | H8: =IFERROR(AVERAGEIFS('RD Condos'!$D:$D,'RD Condos'!$K:$K,$B8,'RD Condos'!$A:$A,1),"") -> 4255.5179 | I8: =IFERROR(AVERAGEIFS('RD Condos'!$F:$F,'RD Condos'!$K:$K,$B8,'RD Condos'!$A:$A,1),"") -> 4.3910833
B9: Ten York | C9: ='Building Summary'!E7 -> 2019 | D9: =IFERROR(AVERAGEIFS('RD Condos'!$J:$J,'RD Condos'!$K:$K,$B9,'RD Condos'!$A:$A,1),"") -> 45923.988 | F9: ='Building Summary'!J7 -> 168 | G9: ='Building Summary'!K7 -> 717.40476 | H9: =IFERROR(AVERAGEIFS('RD Condos'!$D:$D,'RD Condos'!$K:$K,$B9,'RD Condos'!$A:$A,1),"") -> 2916.5417 | I9: =IFERROR(AVERAGEIFS('RD Condos'!$F:$F,'RD Condos'!$K:$K,$B9,'RD Condos'!$A:$A,1),"") -> 4.0347825
B10: Forward Condos | C10: ='Building Summary'!E8 -> 2018 | D10: =IFERROR(AVERAGEIFS('RD Condos'!$J:$J,'RD Condos'!$K:$K,$B10,'RD Condos'!$A:$A,1),"") -> 45934.954 | F10: ='Building Summary'!J8 -> 153 | G10: ='Building Summary'!K8 -> 643.80392 | H10: =IFERROR(AVERAGEIFS('RD Condos'!$D:$D,'RD Condos'!$K:$K,$B10,'RD Condos'!$A:$A,1),"") -> 2674.5425 | I10: =IFERROR(AVERAGEIFS('RD Condos'!$F:$F,'RD Condos'!$K:$K,$B10,'RD Condos'!$A:$A,1),"") -> 4.2030433
B11: Quartz / Spectra | C11: ='Building Summary'!E9 -> 2015 | D11: =IFERROR(AVERAGEIFS('RD Condos'!$J:$J,'RD Condos'!$K:$K,$B11,'RD Condos'!$A:$A,1),"") | F11: ='Building Summary'!J9 -> 0 | G11: ='Building Summary'!K9 | H11: =IFERROR(AVERAGEIFS('RD Condos'!$D:$D,'RD Condos'!$K:$K,$B11,'RD Condos'!$A:$A,1),"") | I11: =IFERROR(AVERAGEIFS('RD Condos'!$F:$F,'RD Condos'!$K:$K,$B11,'RD Condos'!$A:$A,1),"")
B12: Library District | C12: ='Building Summary'!E10 -> 2014 | D12: =IFERROR(AVERAGEIFS('RD Condos'!$J:$J,'RD Condos'!$K:$K,$B12,'RD Condos'!$A:$A,1),"") -> 45901.103 | F12: ='Building Summary'!J10 -> 68 | G12: ='Building Summary'!K10 -> 541.58824 | H12: =IFERROR(AVERAGEIFS('RD Condos'!$D:$D,'RD Condos'!$K:$K,$B12,'RD Condos'!$A:$A,1),"") -> 2272.1324 | I12: =IFERROR(AVERAGEIFS('RD Condos'!$F:$F,'RD Condos'!$K:$K,$B12,'RD Condos'!$A:$A,1),"") -> 4.2769048
B13: N1 | N2 CityPlace | C13: ='Building Summary'!E11 -> 2008 | D13: =IFERROR(AVERAGEIFS('RD Condos'!$J:$J,'RD Condos'!$K:$K,$B13,'RD Condos'!$A:$A,1),"") -> 45917.828 | F13: ='Building Summary'!J11 -> 99 | G13: ='Building Summary'!K11 -> 711.22222 | H13: =IFERROR(AVERAGEIFS('RD Condos'!$D:$D,'RD Condos'!$K:$K,$B13,'RD Condos'!$A:$A,1),"") -> 2733.4242 | I13: =IFERROR(AVERAGEIFS('RD Condos'!$F:$F,'RD Condos'!$K:$K,$B13,'RD Condos'!$A:$A,1),"") -> 3.9035885
B14: Aqua | C14: ='Building Summary'!E12 -> 2003 | D14: =IFERROR(AVERAGEIFS('RD Condos'!$J:$J,'RD Condos'!$K:$K,$B14,'RD Condos'!$A:$A,1),"") -> 45973.806 | F14: ='Building Summary'!J12 -> 31 | G14: ='Building Summary'!K12 -> 701.32258 | H14: =IFERROR(AVERAGEIFS('RD Condos'!$D:$D,'RD Condos'!$K:$K,$B14,'RD Condos'!$A:$A,1),"") -> 2612.2581 | I14: =IFERROR(AVERAGEIFS('RD Condos'!$F:$F,'RD Condos'!$K:$K,$B14,'RD Condos'!$A:$A,1),"") -> 3.7915361
B15: Average | F15: =COUNTIFS('RD Condos'!$A:$A,1) -> 1068 | G15: =IFERROR(AVERAGEIFS('RD Condos'!$B:$B,'RD Condos'!$A:$A,1),"") -> 683.98315 | H15: =IFERROR(AVERAGEIFS('RD Condos'!$D:$D,'RD Condos'!$A:$A,1),"") -> 2850.2097 | I15: =IFERROR(AVERAGEIFS('RD Condos'!$F:$F,'RD Condos'!$A:$A,1),"") -> 4.1972915
B16: PBR Premium | H16: =Data_Summary!C4 -> 0.057662214 | I16: =Data_Summary!C4 -> 0.057662214
B17: Implied Untrended Rent | G17: =G15 -> 683.98315 | H17: =IFERROR(H15*(1+H16),"") -> 3014.5591 | I17: =IFERROR(I15*(1+I16),"") -> 4.4393166
B19: Subject Site (Untrended Rent) | G19: =G17 -> 683.98315 | H19: =H17 -> 3014.5591 | I19: =I17 -> 4.4393166
B21: Other Excluded
B22: Quartz / Spectra (75-85 Queens Wharf Rd, 2015) — selected as a comp; 230 in-window leases pulled, but condos.ca publishes NO per-unit registered area for this corporation, so 0 cleared the exact-or-blank SF bar this session (Route A vipcondos plan-by-stack not re-run). Excluded from $/SF; recorded in the verification log.
B23: PBR / apartment track (same-product comps for the PBR subject): nearby purpose-built rentals found on rentals.ca — 25 Lower Simcoe St, 30 Grand Trunk Cres, 15 Fort York Blvd, 8 Mercer St, 39 Niagara St, 33 Bay St, 16 Yonge St. All publish ASKING rent only with no verified floor-plan SF, so none cleared the SF bar; excluded from $/SF (asking-only). Listed for the premium-basis discussion only.
B24: Evaluated & excluded (location/vintage): Sugar Wharf (95 Lake Shore E — different micro-market); Lighthouse / Aquabella / Aqualuna (East Bayfront ~2.5 km); Bisha / King Blue / Theatre Park (Entertainment District); older CityPlace (Optima/Apex/Montage/Neo/Luna/Parade/West One/Harbour View — redundant with the CityPlace floor already included via N1|N2 + Library).
B25: Weighted Average (all comps) | F25: =COUNTIFS('RD Condos'!$A:$A,1) -> 1068 | G25: =IFERROR(AVERAGEIFS('RD Condos'!$B:$B,'RD Condos'!$A:$A,1),"") -> 683.98315 | H25: =IFERROR(AVERAGEIFS('RD Condos'!$D:$D,'RD Condos'!$A:$A,1),"") -> 2850.2097 | I25: =IFERROR(AVERAGEIFS('RD Condos'!$F:$F,'RD Condos'!$A:$A,1),"") -> 4.1972915
B26: PBR Premium | H26: =Data_Summary!C4 -> 0.057662214 | I26: =Data_Summary!C4 -> 0.057662214
B27: Implied Untrended Rent | H27: =IFERROR(H25*(1+H26),"") -> 3014.5591 | I27: =IFERROR(I25*(1+I26),"") -> 4.4393166 | L27: Studio Units | P27: 1-Bedroom Units | T27: 1-Bedroom + Den Units | X27: 2-Bedroom Units | AB27: 3-Bedroom Units
K28: Building | L28: Transaction Count | M28: Avg. Suite Size | N28: Adj. Avg. Rent | O28: Avg. Net Rent PSF | P28: Transaction Count | Q28: Avg. Suite Size | R28: Adj. Avg. Rent | S28: Avg. Net Rent PSF | T28: Transaction Count | U28: Avg. Suite Size | V28: Adj. Avg. Rent | W28: Avg. Net Rent PSF | X28: Transaction Count | Y28: Avg. Suite Size | Z28: Adj. Avg. Rent | AA28: Avg. Net Rent PSF | AB28: Transaction Count | AC28: Avg. Suite Size | AD28: Adj. Avg. Rent | AE28: Avg. Net Rent PSF
K29: Concord Canada House | L29: =COUNTIFS('RD Condos'!$H:$H,"0",'RD Condos'!$A:$A,1,'RD Condos'!$K:$K,"Concord Canada House") -> 0 | M29: =IFERROR(AVERAGEIFS('RD Condos'!$B:$B,'RD Condos'!$H:$H,"0",'RD Condos'!$A:$A,1,'RD Condos'!$K:$K,"Concord Canada House"),"") | N29: =IFERROR(AVERAGEIFS('RD Condos'!$D:$D,'RD Condos'!$H:$H,"0",'RD Condos'!$A:$A,1,'RD Condos'!$K:$K,"Concord Canada House"),"") | O29: =IFERROR(AVERAGEIFS('RD Condos'!$F:$F,'RD Condos'!$H:$H,"0",'RD Condos'!$A:$A,1,'RD Condos'!$K:$K,"Concord Canada House"),"") | P29: =COUNTIFS('RD Condos'!$Q:$Q,"1",'RD Condos'!$A:$A,1,'RD Condos'!$K:$K,"Concord Canada House") -> 140 | Q29: =IFERROR(AVERAGEIFS('RD Condos'!$B:$B,'RD Condos'!$Q:$Q,"1",'RD Condos'!$A:$A,1,'RD Condos'!$K:$K,"Concord Canada House"),"") -> 525.17857 | R29: =IFERROR(AVERAGEIFS('RD Condos'!$D:$D,'RD Condos'!$Q:$Q,"1",'RD Condos'!$A:$A,1,'RD Condos'!$K:$K,"Concord Canada House"),"") -> 2262.0357 | S29: =IFERROR(AVERAGEIFS('RD Condos'!$F:$F,'RD Condos'!$Q:$Q,"1",'RD Condos'!$A:$A,1,'RD Condos'!$K:$K,"Concord Canada House"),"") -> 4.3297501 | T29: =COUNTIFS('RD Condos'!$Q:$Q,"1+1",'RD Condos'!$A:$A,1,'RD Condos'!$K:$K,"Concord Canada House") -> 55 | U29: =IFERROR(AVERAGEIFS('RD Condos'!$B:$B,'RD Condos'!$Q:$Q,"1+1",'RD Condos'!$A:$A,1,'RD Condos'!$K:$K,"Concord Canada House"),"") -> 583.87273 | V29: =IFERROR(AVERAGEIFS('RD Condos'!$D:$D,'RD Condos'!$Q:$Q,"1+1",'RD Condos'!$A:$A,1,'RD Condos'!$K:$K,"Concord Canada House"),"") -> 2562.9091 | W29: =IFERROR(AVERAGEIFS('RD Condos'!$F:$F,'RD Condos'!$Q:$Q,"1+1",'RD Condos'!$A:$A,1,'RD Condos'!$K:$K,"Concord Canada House"),"") -> 4.4237924 | X29: =COUNTIFS('RD Condos'!$H:$H,"2",'RD Condos'!$A:$A,1,'RD Condos'!$K:$K,"Concord Canada House") -> 74 | Y29: =IFERROR(AVERAGEIFS('RD Condos'!$B:$B,'RD Condos'!$H:$H,"2",'RD Condos'!$A:$A,1,'RD Condos'!$K:$K,"Concord Canada House"),"") -> 783.13514 | Z29: =IFERROR(AVERAGEIFS('RD Condos'!$D:$D,'RD Condos'!$H:$H,"2",'RD Condos'!$A:$A,1,'RD Condos'!$K:$K,"Concord Canada House"),"") -> 3163.5135 | AA29: =IFERROR(AVERAGEIFS('RD Condos'!$F:$F,'RD Condos'!$H:$H,"2",'RD Condos'!$A:$A,1,'RD Condos'!$K:$K,"Concord Canada House"),"") -> 4.0793779 | AB29: =COUNTIFS('RD Condos'!$H:$H,"3",'RD Condos'!$A:$A,1,'RD Condos'!$K:$K,"Concord Canada House") -> 15 | AC29: =IFERROR(AVERAGEIFS('RD Condos'!$B:$B,'RD Condos'!$H:$H,"3",'RD Condos'!$A:$A,1,'RD Condos'!$K:$K,"Concord Canada House"),"") -> 1008 | AD29: =IFERROR(AVERAGEIFS('RD Condos'!$D:$D,'RD Condos'!$H:$H,"3",'RD Condos'!$A:$A,1,'RD Condos'!$K:$K,"Concord Canada House"),"") -> 4053.3333 | AE29: =IFERROR(AVERAGEIFS('RD Condos'!$F:$F,'RD Condos'!$H:$H,"3",'RD Condos'!$A:$A,1,'RD Condos'!$K:$K,"Concord Canada House"),"") -> 4.2261792
B30: ★ RECOMMENDATION — RECOMMENDED SUBJECT RENT
B31: Recommended subject $/SF | D31: =Data_Summary!$C$34 -> 4.5552938 | K31: Weighted Avg. | L31: =COUNTIFS('RD Condos'!$H:$H,"0",'RD Condos'!$A:$A,1) -> 1 | M31: =IFERROR(AVERAGEIFS('RD Condos'!$B:$B,'RD Condos'!$H:$H,"0",'RD Condos'!$A:$A,1),"") -> 403 | N31: =IFERROR(AVERAGEIFS('RD Condos'!$D:$D,'RD Condos'!$H:$H,"0",'RD Condos'!$A:$A,1),"") -> 2000 | O31: =IFERROR(AVERAGEIFS('RD Condos'!$F:$F,'RD Condos'!$H:$H,"0",'RD Condos'!$A:$A,1),"") -> 4.9627792 | P31: =COUNTIFS('RD Condos'!$Q:$Q,"1",'RD Condos'!$A:$A,1) -> 387 | Q31: =IFERROR(AVERAGEIFS('RD Condos'!$B:$B,'RD Condos'!$Q:$Q,"1",'RD Condos'!$A:$A,1),"") -> 533.67959 | R31: =IFERROR(AVERAGEIFS('RD Condos'!$D:$D,'RD Condos'!$Q:$Q,"1",'RD Condos'!$A:$A,1),"") -> 2283.5245 | S31: =IFERROR(AVERAGEIFS('RD Condos'!$F:$F,'RD Condos'!$Q:$Q,"1",'RD Condos'!$A:$A,1),"") -> 4.3127562 | T31: =COUNTIFS('RD Condos'!$Q:$Q,"1+1",'RD Condos'!$A:$A,1) -> 235 | U31: =IFERROR(AVERAGEIFS('RD Condos'!$B:$B,'RD Condos'!$Q:$Q,"1+1",'RD Condos'!$A:$A,1),"") -> 612.66809 | V31: =IFERROR(AVERAGEIFS('RD Condos'!$D:$D,'RD Condos'!$Q:$Q,"1+1",'RD Condos'!$A:$A,1),"") -> 2483.6128 | W31: =IFERROR(AVERAGEIFS('RD Condos'!$F:$F,'RD Condos'!$Q:$Q,"1+1",'RD Condos'!$A:$A,1),"") -> 4.0778679 | X31: =COUNTIFS('RD Condos'!$H:$H,"2",'RD Condos'!$A:$A,1) -> 371 | Y31: =IFERROR(AVERAGEIFS('RD Condos'!$B:$B,'RD Condos'!$H:$H,"2",'RD Condos'!$A:$A,1),"") -> 801.84097 | Z31: =IFERROR(AVERAGEIFS('RD Condos'!$D:$D,'RD Condos'!$H:$H,"2",'RD Condos'!$A:$A,1),"") -> 3315.5202 | AA31: =IFERROR(AVERAGEIFS('RD Condos'!$F:$F,'RD Condos'!$H:$H,"2",'RD Condos'!$A:$A,1),"") -> 4.148316 | AB31: =COUNTIFS('RD Condos'!$H:$H,"3",'RD Condos'!$A:$A,1) -> 74 | AC31: =IFERROR(AVERAGEIFS('RD Condos'!$B:$B,'RD Condos'!$H:$H,"3",'RD Condos'!$A:$A,1),"") -> 1109.4189 | AD31: =IFERROR(AVERAGEIFS('RD Condos'!$D:$D,'RD Condos'!$H:$H,"3",'RD Condos'!$A:$A,1),"") -> 4656.6622 | AE31: =IFERROR(AVERAGEIFS('RD Condos'!$F:$F,'RD Condos'!$H:$H,"3",'RD Condos'!$A:$A,1),"") -> 4.2078873
B32: Conservative (all-comp + premium) $/SF | D32: =Data_Summary!$C$35 -> 4.5108918 | K32: Low | O32: =IFERROR(SUMPRODUCT(MIN(IF((('RD Condos'!$H$2:$H$1069="0")*('RD Condos'!$A$2:$A$1069=1)),'RD Condos'!$F$2:$F$1069))),"") -> 4.9627792 | S32: =IFERROR(SUMPRODUCT(MIN(IF((('RD Condos'!$Q$2:$Q$1069="1")*('RD Condos'!$A$2:$A$1069=1)),'RD Condos'!$F$2:$F$1069))),"") -> 2.5543478 | W32: =IFERROR(SUMPRODUCT(MIN(IF((('RD Condos'!$Q$2:$Q$1069="1+1")*('RD Condos'!$A$2:$A$1069=1)),'RD Condos'!$F$2:$F$1069))),"") -> 2.8678304 | AA32: =IFERROR(SUMPRODUCT(MIN(IF((('RD Condos'!$H$2:$H$1069="2")*('RD Condos'!$A$2:$A$1069=1)),'RD Condos'!$F$2:$F$1069))),"") -> 2.2334294 | AE32: =IFERROR(SUMPRODUCT(MIN(IF((('RD Condos'!$H$2:$H$1069="3")*('RD Condos'!$A$2:$A$1069=1)),'RD Condos'!$F$2:$F$1069))),"") -> 2.9247911
B33: Raw comp $/SF (Concord Canada House, no premium) | D33: =Data_Summary!$C$31 -> 4.3069458 | K33: High | O33: =IFERROR(SUMPRODUCT(MAX(IF((('RD Condos'!$H$2:$H$1069="0")*('RD Condos'!$A$2:$A$1069=1)),'RD Condos'!$F$2:$F$1069))),"") -> 4.9627792 | S33: =IFERROR(SUMPRODUCT(MAX(IF((('RD Condos'!$Q$2:$Q$1069="1")*('RD Condos'!$A$2:$A$1069=1)),'RD Condos'!$F$2:$F$1069))),"") -> 7.4074074 | W33: =IFERROR(SUMPRODUCT(MAX(IF((('RD Condos'!$Q$2:$Q$1069="1+1")*('RD Condos'!$A$2:$A$1069=1)),'RD Condos'!$F$2:$F$1069))),"") -> 5.4205607 | AA33: =IFERROR(SUMPRODUCT(MAX(IF((('RD Condos'!$H$2:$H$1069="2")*('RD Condos'!$A$2:$A$1069=1)),'RD Condos'!$F$2:$F$1069))),"") -> 6.5934066 | AE33: =IFERROR(SUMPRODUCT(MAX(IF((('RD Condos'!$H$2:$H$1069="3")*('RD Condos'!$A$2:$A$1069=1)),'RD Condos'!$F$2:$F$1069))),"") -> 6.8807339
B34: Plus — new-build / lease-up premium | D34: =Data_Summary!$C$4 -> 0.057662214
K35: PBR Premium | O35: =Data_Summary!$C$4 -> 0.057662214 | S35: =Data_Summary!$C$4 -> 0.057662214 | W35: =Data_Summary!$C$4 -> 0.057662214 | AA35: =Data_Summary!$C$4 -> 0.057662214 | AE35: =Data_Summary!$C$4 -> 0.057662214
B36: Recommended monthly rent by suite type | K36: Weighted Avg. (×(1+PBR)) | N36: =IFERROR(N31*(1+$O$35),"") -> 2115.3244 | O36: =IFERROR(O31*(1+O35),"") -> 5.248944 | R36: =IFERROR(R31*(1+$S$35),"") -> 2415.1976 | S36: =IFERROR(S31*(1+S35),"") -> 4.5614393 | V36: =IFERROR(V31*(1+$W$35),"") -> 2626.8234 | W36: =IFERROR(W31*(1+W35),"") -> 4.3130068 | Z36: =IFERROR(Z31*(1+$AA$35),"") -> 3506.7005 | AA36: =IFERROR(AA31*(1+AA35),"") -> 4.3875171 | AD36: =IFERROR(AD31*(1+$AE$35),"") -> 4925.1756 | AE36: =IFERROR(AE31*(1+AE35),"") -> 4.4505234
B37: Suite | C37: Avg SF | D37: Rec. Rent | K37: Weighted Avg. Building Total (Comps) | L37: =IFERROR((R31*Data_Summary!$T$3+V31*Data_Summary!$T$4+Z31*Data_Summary!$T$5+AD31*Data_Summary!$T$6)*Data_Summary!$T$2,"") -> 1428377.2
B38: 1-Bed / 1+Den | C38: =Data_Summary!C26 -> 541.73333 | D38: =Data_Summary!F26 -> 2483.8519
B39: 2-Bed | C39: =Data_Summary!C27 -> 783.13514 | D39: =Data_Summary!F27 -> 3433.829 | K39: Subject Property (Using Comp $ Rent) | N39: =IFERROR(N36,"") -> 2115.3244 | R39: =IFERROR(R36,"") -> 2415.1976 | V39: =IFERROR(V36,"") -> 2626.8234 | Z39: =IFERROR(Z36,"") -> 3506.7005 | AD39: =IFERROR(AD36,"") -> 4925.1756
B40: 3-Bed | C40: =Data_Summary!C28 -> 1008 | D40: =Data_Summary!F28 -> 4435.1302 | K40: Subject Property Rent Building Total | L40: =IFERROR((R39*Data_Summary!$T$3+V39*Data_Summary!$T$4+Z39*Data_Summary!$T$5+AD39*Data_Summary!$T$6)*Data_Summary!$T$2,"") -> 1510740.6
B42: Custom suite — enter size (sq ft) → | D42: 700 | K42: Subject Property (Using Comp PSF Rent) | N42: =IFERROR(O36*M31,"") -> 2115.3244 | R42: =IFERROR(S36*Q31,"") -> 2434.347 | V42: =IFERROR(W36*U31,"") -> 2642.4416 | Z42: =IFERROR(AA36*Y31,"") -> 3518.091 | AD42: =IFERROR(AE36*AC31,"") -> 4937.4949
B43: Implied rent @ recommended subject $/SF | D43: =IFERROR(D42*Data_Summary!$C$34,"") -> 3188.7057 | K43: Subject Property PSF Rent Building Total | L43: =IFERROR((R42*Data_Summary!$T$3+V42*Data_Summary!$T$4+Z42*Data_Summary!$T$5+AD42*Data_Summary!$T$6)*Data_Summary!$T$2,"") -> 1518767.4
B44: Implied rent @ raw comp $/SF (no premium) | D44: =IFERROR(D42*Data_Summary!$C$31,"") -> 3014.8621
K45: Subject Property Rent | N45: =IFERROR(AVERAGE(N39,N42),"") -> 2115.3244 | R45: =IFERROR(AVERAGE(R39,R42),"") -> 2424.7723 | V45: =IFERROR(AVERAGE(V39,V42),"") -> 2634.6325 | Z45: =IFERROR(AVERAGE(Z39,Z42),"") -> 3512.3957 | AD45: =IFERROR(AVERAGE(AD39,AD42),"") -> 4931.3353
...

Sheet Building Summary
A1: Comp Building Summary — 10 Lower Spadina (PBR scenario) (10 Lower Spadina Ave, Waterfront / C01)
A3: Building | B3: Address | C3: Area | D3: Developer | E3: First Occupancy | F3: Yr Built | G3: Product | H3: Storeys | I3: Units | J3: Transaction Count | K3: Avg SF | L3: Avg Rent | M3: Avg $/SF
A4: Concord Canada House | B4: 23 Spadina Ave | C4: CityPlace | D4: Concord Adex | E4: 2025 | F4: 2025 | G4: Condo | J4: =COUNTIFS('RD Condos'!$K:$K,$A4,'RD Condos'!$A:$A,1) -> 284 | K4: =IFERROR(AVERAGEIFS('RD Condos'!$B:$B,'RD Condos'!$K:$K,$A4,'RD Condos'!$A:$A,1),"") -> 629.26056 | L4: =IFERROR(AVERAGEIFS('RD Condos'!$AB:$AB,'RD Condos'!$K:$K,$A4,'RD Condos'!$A:$A,1),"") -> 2679.912 | M4: =IFERROR(AVERAGEIFS('RD Condos'!$E:$E,'RD Condos'!$K:$K,$A4,'RD Condos'!$A:$A,1),"") -> 4.3137755
A5: Nobu Residences | B5: 15 Mercer St | C5: Entertainment District | D5: Madison Group | E5: 2024 | F5: 2024 | G5: Condo | J5: =COUNTIFS('RD Condos'!$K:$K,$A5,'RD Condos'!$A:$A,1) -> 209 | K5: =IFERROR(AVERAGEIFS('RD Condos'!$B:$B,'RD Condos'!$K:$K,$A5,'RD Condos'!$A:$A,1),"") -> 720.84211 | L5: =IFERROR(AVERAGEIFS('RD Condos'!$AB:$AB,'RD Condos'!$K:$K,$A5,'RD Condos'!$A:$A,1),"") -> 3128.6699 | M5: =IFERROR(AVERAGEIFS('RD Condos'!$E:$E,'RD Condos'!$K:$K,$A5,'RD Condos'!$A:$A,1),"") -> 4.3690416
A6: The Well | B6: 470-486 Front St W | C6: King West | D6: Tridel / RioCan | E6: 2024 | F6: 2024 | G6: Condo | J6: =COUNTIFS('RD Condos'!$K:$K,$A6,'RD Condos'!$A:$A,1) -> 56 | K6: =IFERROR(AVERAGEIFS('RD Condos'!$B:$B,'RD Condos'!$K:$K,$A6,'RD Condos'!$A:$A,1),"") -> 948.60714 | L6: =IFERROR(AVERAGEIFS('RD Condos'!$AB:$AB,'RD Condos'!$K:$K,$A6,'RD Condos'!$A:$A,1),"") -> 4351.9464 | M6: =IFERROR(AVERAGEIFS('RD Condos'!$E:$E,'RD Condos'!$K:$K,$A6,'RD Condos'!$A:$A,1),"") -> 4.4763158
A7: Ten York | B7: 10 York St | C7: Waterfront | D7: Tridel | E7: 2019 | F7: 2019 | G7: Condo | J7: =COUNTIFS('RD Condos'!$K:$K,$A7,'RD Condos'!$A:$A,1) -> 168 | K7: =IFERROR(AVERAGEIFS('RD Condos'!$B:$B,'RD Condos'!$K:$K,$A7,'RD Condos'!$A:$A,1),"") -> 717.40476 | L7: =IFERROR(AVERAGEIFS('RD Condos'!$AB:$AB,'RD Condos'!$K:$K,$A7,'RD Condos'!$A:$A,1),"") -> 2964.756 | M7: =IFERROR(AVERAGEIFS('RD Condos'!$E:$E,'RD Condos'!$K:$K,$A7,'RD Condos'!$A:$A,1),"") -> 4.0902089
A8: Forward Condos | B8: 70-90 Queens Wharf Rd | C8: CityPlace | D8: Concord Adex | E8: 2018 | F8: 2018 | G8: Condo | J8: =COUNTIFS('RD Condos'!$K:$K,$A8,'RD Condos'!$A:$A,1) -> 153 | K8: =IFERROR(AVERAGEIFS('RD Condos'!$B:$B,'RD Condos'!$K:$K,$A8,'RD Condos'!$A:$A,1),"") -> 643.80392 | L8: =IFERROR(AVERAGEIFS('RD Condos'!$AB:$AB,'RD Condos'!$K:$K,$A8,'RD Condos'!$A:$A,1),"") -> 2743.1699 | M8: =IFERROR(AVERAGEIFS('RD Condos'!$E:$E,'RD Condos'!$K:$K,$A8,'RD Condos'!$A:$A,1),"") -> 4.303167
A9: Quartz / Spectra | B9: 75-85 Queens Wharf Rd | C9: CityPlace | D9: Concord Adex | E9: 2015 | F9: 2015 | G9: Condo | J9: =COUNTIFS('RD Condos'!$K:$K,$A9,'RD Condos'!$A:$A,1) -> 0 | K9: =IFERROR(AVERAGEIFS('RD Condos'!$B:$B,'RD Condos'!$K:$K,$A9,'RD Condos'!$A:$A,1),"") | L9: =IFERROR(AVERAGEIFS('RD Condos'!$AB:$AB,'RD Condos'!$K:$K,$A9,'RD Condos'!$A:$A,1),"") | M9: =IFERROR(AVERAGEIFS('RD Condos'!$E:$E,'RD Condos'!$K:$K,$A9,'RD Condos'!$A:$A,1),"")
A10: Library District | B10: 170 Fort York Blvd | C10: CityPlace | D10: Concord Adex | E10: 2014 | F10: 2014 | G10: Condo | J10: =COUNTIFS('RD Condos'!$K:$K,$A10,'RD Condos'!$A:$A,1) -> 68 | K10: =IFERROR(AVERAGEIFS('RD Condos'!$B:$B,'RD Condos'!$K:$K,$A10,'RD Condos'!$A:$A,1),"") -> 541.58824 | L10: =IFERROR(AVERAGEIFS('RD Condos'!$AB:$AB,'RD Condos'!$K:$K,$A10,'RD Condos'!$A:$A,1),"") -> 2329.4853 | M10: =IFERROR(AVERAGEIFS('RD Condos'!$E:$E,'RD Condos'!$K:$K,$A10,'RD Condos'!$A:$A,1),"") -> 4.3747615
A11: N1 | N2 CityPlace | B11: 15 Fort York Blvd | C11: CityPlace | D11: Concord Adex | E11: 2008 | F11: 2008 | G11: Condo | J11: =COUNTIFS('RD Condos'!$K:$K,$A11,'RD Condos'!$A:$A,1) -> 99 | K11: =IFERROR(AVERAGEIFS('RD Condos'!$B:$B,'RD Condos'!$K:$K,$A11,'RD Condos'!$A:$A,1),"") -> 711.22222 | L11: =IFERROR(AVERAGEIFS('RD Condos'!$AB:$AB,'RD Condos'!$K:$K,$A11,'RD Condos'!$A:$A,1),"") -> 2839.4848 | M11: =IFERROR(AVERAGEIFS('RD Condos'!$E:$E,'RD Condos'!$K:$K,$A11,'RD Condos'!$A:$A,1),"") -> 4.0501137
A12: Aqua | B12: 410 Queens Quay W | C12: Waterfront | D12: Monarch | E12: 2003 | F12: 2003 | G12: Condo | J12: =COUNTIFS('RD Condos'!$K:$K,$A12,'RD Condos'!$A:$A,1) -> 31 | K12: =IFERROR(AVERAGEIFS('RD Condos'!$B:$B,'RD Condos'!$K:$K,$A12,'RD Condos'!$A:$A,1),"") -> 701.32258 | L12: =IFERROR(AVERAGEIFS('RD Condos'!$AB:$AB,'RD Condos'!$K:$K,$A12,'RD Condos'!$A:$A,1),"") -> 2699.3548 | M12: =IFERROR(AVERAGEIFS('RD Condos'!$E:$E,'RD Condos'!$K:$K,$A12,'RD Condos'!$A:$A,1),"") -> 3.9085518
A13: ALL CONDOS | J13: =SUM(J4:J12) -> 1068 | K13: =IFERROR(AVERAGEIFS('RD Condos'!$B:$B,'RD Condos'!$A:$A,1),"") -> 683.98315 | L13: =IFERROR(AVERAGEIFS('RD Condos'!$AB:$AB,'RD Condos'!$A:$A,1),"") -> 2902.3165 | M13: =IFERROR(AVERAGEIFS('RD Condos'!$AN:$AN,'RD Condos'!$A:$A,1),"") -> 4.2641062
A14: ALL APARTMENTS | J14: =COUNTIFS('RD Apartments'!$A:$A,1) -> 0 | K14: =IFERROR(AVERAGEIFS('RD Apartments'!$B:$B,'RD Apartments'!$A:$A,1),"") | L14: =IFERROR(AVERAGEIFS('RD Apartments'!$AB:$AB,'RD Apartments'!$A:$A,1),"") | M14: =IFERROR(AVERAGEIFS('RD Apartments'!$AN:$AN,'RD Apartments'!$A:$A,1),"")

Sheet Data_Summary
B1: Date Filter (include leases on/after) | C1: 45658 | D1: lever — trailing window; leases on/after this date count. Tunable. | G1: Subject unit mix (1BR/2BR/3BR, den-incl) — DERIVED | P1: Subject Unit-Mix Derivation (P/Q) | S1: Subject Output mix & suite count
B2: Parking Adjustment ($/spot/mo) | C2: 150 | D2: Area parking comps, downtown waterfront: standalone spots ~$200-250/mo; observed with-vs-without-parking rent uplift is modest (most CityPlace/waterfront comps lease w/o parking). Tunable lever; prior model used a near-zero LINEST value. condos.ca, 2026-06-22. | G2: 1BR wt | H2: =IF($Q$5>0,$Q$2/$Q$5,$Q$8) -> 0.63 | P2: 1BR plans (SUBJECT, den-incl) | Q2: =COUNTIFS('Floor Plans'!$A:$A,"*(SUBJECT)*",'Floor Plans'!$I:$I,"<=1") -> 0 | S2: Suite count | T2: 511 | U2: vipcondos Step 0 2026-06-22: 511 suites / 49 storeys.
B3: Apartment premium (apt comps only) — OFF | C3: 0 | D3: No APARTMENT COMP rows in the set (PBR track found only asking-only listings with no verified SF — see notes). Condo→PBR premium for the subject is ~10% (external/prior-model anchor); applied as a DOWNWARD bridge to the condo-equivalent recommendation in the PBR summary, not via this lever. | G3: 2BR wt | H3: =IF($Q$5>0,$Q$3/$Q$5,$Q$9) -> 0.3 | P3: 2BR plans (SUBJECT) | Q3: =COUNTIFS('Floor Plans'!$A:$A,"*(SUBJECT)*",'Floor Plans'!$I:$I,2) -> 0 | S3: 1BR wt | T3: 0.45
B4: Subject rental premium (new-build / lease-up; comp $/SF → subject) | C4: =IF(AND(ABS(C61)<0.0001,ABS(C62)<0.0001),0.1,(C61+C62)/2) -> 0.057662214 | D4: DERIVED off PREMIUM BASIS (midpoint of C61 newest/all-comp & C62 newest/oldest). This comp set is single-/equal-vintage ⇒ no spread ⇒ C4 falls back to the sourced subject premium 10.0%: new-build/lease-up premium fallback; brand-new 2029-30 subject vs comp blend. C4 normally DERIVED off the live PREMIUM BASIS vintage spread (2003-2025); this is the fallback only if the comp set were single-vintage. | G4: 3BR wt | H4: =IF($Q$5>0,$Q$4/$Q$5,$Q$10) -> 0.07 | P4: 3BR plans (SUBJECT) | Q4: =COUNTIFS('Floor Plans'!$A:$A,"*(SUBJECT)*",'Floor Plans'!$I:$I,">=3") -> 0 | S4: 1+Den wt | T4: 0.18
P5: Total tagged plans | Q5: =SUM(Q2:Q4) -> 0 | S5: 2BR wt | T5: 0.3
P6: (0 ⇒ falls back to manual mix Q8:Q10) | S6: 3BR wt | T6: 0.07
P7: Source | Q7: estimated downtown-waterfront program 2026-06-22 (den-incl 1BR=1B+1+den); supersede with developer suite schedule (authoritative).
P8: 1BR wt (manual) | Q8: 0.63
P9: 2BR wt (manual) | Q9: 0.3
P10: 3BR wt (manual) | Q10: 0.07
A18: By Bedroom — all comps (den-incl.)
A19: Beds | B19: Incl. | C19: Avg SF | D19: Avg Rent | E19: Avg $/SF
A20: 1 Bed | B20: =COUNTIFS('RD Condos'!$H:$H,"1",'RD Condos'!$A:$A,1) -> 622 | C20: =IFERROR(AVERAGEIFS('RD Condos'!$B:$B,'RD Condos'!$H:$H,"1",'RD Condos'!$A:$A,1),"") -> 563.52251 | D20: =IFERROR(AVERAGEIFS('RD Condos'!$AB:$AB,'RD Condos'!$H:$H,"1",'RD Condos'!$A:$A,1),"") -> 2385.1656 | E20: =IFERROR(AVERAGEIFS('RD Condos'!$AN:$AN,'RD Condos'!$H:$H,"1",'RD Condos'!$A:$A,1),"") -> 4.2686643
A21: 2 Bed | B21: =COUNTIFS('RD Condos'!$H:$H,"2",'RD Condos'!$A:$A,1) -> 371 | C21: =IFERROR(AVERAGEIFS('RD Condos'!$B:$B,'RD Condos'!$H:$H,"2",'RD Condos'!$A:$A,1),"") -> 801.84097 | D21: =IFERROR(AVERAGEIFS('RD Condos'!$AB:$AB,'RD Condos'!$H:$H,"2",'RD Condos'!$A:$A,1),"") -> 3391.531 | E21: =IFERROR(AVERAGEIFS('RD Condos'!$AN:$AN,'RD Condos'!$H:$H,"2",'RD Condos'!$A:$A,1),"") -> 4.2380095
A22: 3 Bed | B22: =COUNTIFS('RD Condos'!$H:$H,"3",'RD Condos'!$A:$A,1) -> 74 | C22: =IFERROR(AVERAGEIFS('RD Condos'!$B:$B,'RD Condos'!$H:$H,"3",'RD Condos'!$A:$A,1),"") -> 1109.4189 | D22: =IFERROR(AVERAGEIFS('RD Condos'!$AB:$AB,'RD Condos'!$H:$H,"3",'RD Condos'!$A:$A,1),"") -> 4808.6892 | E22: =IFERROR(AVERAGEIFS('RD Condos'!$AN:$AN,'RD Condos'!$H:$H,"3",'RD Condos'!$A:$A,1),"") -> 4.3471882
A24: By Bedroom — Concord Canada House only (new-build basis)
A25: Beds | B25: Incl. | C25: Avg SF | D25: Avg Rent | E25: $/SF | F25: Subj Rent (+prem)
A26: 1 Bed | B26: =COUNTIFS('RD Condos'!$K:$K,"Concord Canada House",'RD Condos'!$H:$H,"1",'RD Condos'!$A:$A,1) -> 195 | C26: =IFERROR(AVERAGEIFS('RD Condos'!$B:$B,'RD Condos'!$K:$K,"Concord Canada House",'RD Condos'!$H:$H,"1",'RD Condos'!$A:$A,1),"") -> 541.73333 | D26: =IFERROR(AVERAGEIFS('RD Condos'!$AB:$AB,'RD Condos'!$K:$K,"Concord Canada House",'RD Condos'!$H:$H,"1",'RD Condos'!$A:$A,1),"") -> 2348.4359 | E26: =IFERROR(AVERAGEIFS('RD Condos'!$E:$E,'RD Condos'!$K:$K,"Concord Canada House",'RD Condos'!$H:$H,"1",'RD Condos'!$A:$A,1),"") -> 4.3592359 | F26: =IFERROR(D26*(1+$C$4),"") -> 2483.8519
A27: 2 Bed | B27: =COUNTIFS('RD Condos'!$K:$K,"Concord Canada House",'RD Condos'!$H:$H,"2",'RD Condos'!$A:$A,1) -> 74 | C27: =IFERROR(AVERAGEIFS('RD Condos'!$B:$B,'RD Condos'!$K:$K,"Concord Canada House",'RD Condos'!$H:$H,"2",'RD Condos'!$A:$A,1),"") -> 783.13514 | D27: =IFERROR(AVERAGEIFS('RD Condos'!$AB:$AB,'RD Condos'!$K:$K,"Concord Canada House",'RD Condos'!$H:$H,"2",'RD Condos'!$A:$A,1),"") -> 3246.6216 | E27: =IFERROR(AVERAGEIFS('RD Condos'!$E:$E,'RD Condos'!$K:$K,"Concord Canada House",'RD Condos'!$H:$H,"2",'RD Condos'!$A:$A,1),"") -> 4.1836466 | F27: =IFERROR(D27*(1+$C$4),"") -> 3433.829
A28: 3 Bed | B28: =COUNTIFS('RD Condos'!$K:$K,"Concord Canada House",'RD Condos'!$H:$H,"3",'RD Condos'!$A:$A,1) -> 15 | C28: =IFERROR(AVERAGEIFS('RD Condos'!$B:$B,'RD Condos'!$K:$K,"Concord Canada House",'RD Condos'!$H:$H,"3",'RD Condos'!$A:$A,1),"") -> 1008 | D28: =IFERROR(AVERAGEIFS('RD Condos'!$AB:$AB,'RD Condos'!$K:$K,"Concord Canada House",'RD Condos'!$H:$H,"3",'RD Condos'!$A:$A,1),"") -> 4193.3333 | E28: =IFERROR(AVERAGEIFS('RD Condos'!$E:$E,'RD Condos'!$K:$K,"Concord Canada House",'RD Condos'!$H:$H,"3",'RD Condos'!$A:$A,1),"") -> 4.3647595 | F28: =IFERROR(D28*(1+$C$4),"") -> 4435.1302
A30: SUBJECT RECOMMENDATION (comp $/SF + premium)
A31: Weighted comp $/SF — Concord Canada House basis | C31: =E26*$H$2+E27*$H$3+E28*$H$4 -> 4.3069458
A32: Weighted comp $/SF — all-comp basis | C32: =E20*$H$2+E21*$H$3+E22*$H$4 -> 4.2649645
A33: Subject rental premium | C33: =C4 -> 0.057662214
A34: RECOMMENDED subject $/SF (Concord Canada House + premium) | C34: =C31*(1+C4) -> 4.5552938
A35: Subject $/SF (all-comp + premium) | C35: =C32*(1+C4) -> 4.5108918
A36: Prior model subject | C36: 4.78
A37: Residual vs prior | C37: =IFERROR(C34/C36-1,"") -> -0.047009661
A56: PREMIUM BASIS (live) — vintage $/SF spread anchoring C4
A57: Metric | C57: $/SF
A58: Newest comp (Concord Canada House) avg $/SF | C58: =IFERROR(AVERAGEIFS('RD Condos'!$E:$E,'RD Condos'!$K:$K,"Concord Canada House",'RD Condos'!$A:$A,1),"") -> 4.3137755
A59: All-comp avg $/SF | C59: =IFERROR(AVERAGEIFS('RD Condos'!$AN:$AN,'RD Condos'!$A:$A,1),"") -> 4.2641062
A60: Oldest comp (Aqua) avg $/SF | C60: =IFERROR(AVERAGEIFS('RD Condos'!$E:$E,'RD Condos'!$K:$K,"Aqua",'RD Condos'!$A:$A,1),"") -> 3.9085518
A61: Observed vintage premium — newest / all-comp - 1 | C61: =IFERROR(C58/C59-1,"") -> 0.011648239
A62: Observed vintage premium — newest / oldest - 1 | C62: =IFERROR(C58/C60-1,"") -> 0.10367619
A63: C4 subject premium (sits within observed range) | C63: =C4 -> 0.057662214
A65: MIX BASIS (live) — comp-set bed distribution vs estimated subject mix
A66: Bucket | B66: Comp # | C66: Comp share | D66: Subject est.
A67: 1-Bed (H=1, den-incl) | B67: =COUNTIFS('RD Condos'!$H:$H,"1",'RD Condos'!$A:$A,1) -> 622 | C67: =IFERROR(B67/$B$70,"") -> 0.58294283 | D67: =H2 -> 0.63
A68: 2-Bed (H=2, incl 2+den) | B68: =COUNTIFS('RD Condos'!$H:$H,"2",'RD Condos'!$A:$A,1) -> 371 | C68: =IFERROR(B68/$B$70,"") -> 0.34770384 | D68: =H3 -> 0.3
...

Sheet RD Condos
A1: Include | B1: Sq Ft. | C1: Rent | D1: Adj. Rent | E1: $/sq ft | F1: Adj. $/sq ft | G1: Adj BD | H1: Beds Number | I1: Den | J1: Date | K1: Building Name | L1: Building Address | M1: Building City | N1: Developer | O1: Unit # | P1: Unit Address | Q1: Beds | R1: Baths | S1: Sqft (Condos.ca) | T1: MLS Size Range | U1: # Parking | V1: Parking Included | W1: Locker | X1: Outdoor Space | Y1: Exposure | Z1: Building Age | AA1: Building Amenities | AB1: Leased Rent ($) | AC1: Listed Rent ($) | AD1: PSF (Calculated) | AE1: PSF (Listing) | AF1: Furnished | AG1: Hydro Included | AH1: Water Included | AI1: Lease Date | AJ1: MLS# | AK1: Listing URL | AL1: Description | AM1: Product Type | AN1: $/SF (Product-Adj) | AO1: Date Scraped
A2: =IF(AND(ISNUMBER(B2),B2>0,ISNUMBER(AB2),AB2>0,J2>=Data_Summary!$C$1),1,0) -> 1 | B2: 888 | C2: =IF(ISNUMBER(AB2),AB2,"") -> 3750 | D2: =IF(ISNUMBER(C2),C2-U2*Data_Summary!$C$2,"") -> 3600 | E2: =IFERROR(C2/B2,"") -> 4.222973 | F2: =IFERROR(D2/B2,"") -> 4.0540541 | G2: =Q2 -> 3 | H2: =IFERROR(LEFT(G2,1),"") -> 3 | I2: =IF(LEN(G2)>1,1,0) -> 0 | J2: 46191 | K2: Concord Canada House | L2: 23 Spadina Ave | M2: Toronto | N2: Concord Adex | O2: 929 | Q2: 3 | R2: 2 | S2: 888 | T2: 800-899 sqft | U2: 1 | V2: Yes | W2: Owned | X2: Balcony, Patio | Y2: NW | Z2: Built 2025 (1 yrs) | AA2: Concierge, Gym, Party Room, Outdoor Terrace | AB2: 3750 | AC2: 3950 | AD2: =IFERROR(AB2/B2,"") -> 4.222973 | AE2: =IFERROR(AC2/B2,"") -> 4.4481982 | AF2: No | AG2: No | AH2: Yes | AI2: 2026-06-18 | AJ2: C13434728 | AK2: https://condos.ca/toronto/concord-canada-house-23-spadina-ave-1-3-concord-cityplace-way/unit-929-C13434728 | AL2: condos.ca registered area 888 sqft* (source Calculated), in MLS bracket 800-899; leased 2026-06-18. | AM2: Condo | AN2: =IFERROR(E2*(1+IF(AM2="Apartment",Data_Summary!$C$3,0)),"") -> 4.222973 | AO2: 46195
A3: =IF(AND(ISNUMBER(B3),B3>0,ISNUMBER(AB3),AB3>0,J3>=Data_Summary!$C$1),1,0) -> 1 | B3: 505 | C3: =IF(ISNUMBER(AB3),AB3,"") -> 2300 | D3: =IF(ISNUMBER(C3),C3-U3*Data_Summary!$C$2,"") -> 2300 | E3: =IFERROR(C3/B3,"") -> 4.5544554 | F3: =IFERROR(D3/B3,"") -> 4.5544554 | G3: =Q3 -> 1 | H3: =IFERROR(LEFT(G3,1),"") -> 1 | I3: =IF(LEN(G3)>1,1,0) -> 0 | J3: 46190 | K3: Concord Canada House | L3: 23 Spadina Ave | M3: Toronto | N3: Concord Adex | O3: 4302 | Q3: 1 | R3: 1 | S3: 505 | T3: 500-599 sqft | U3: 0 | V3: Yes | W3: None | X3: Balcony, Patio | Y3: W | Z3: Built 2025 (1 yrs) | AA3: Concierge, Gym, Party Room, Outdoor Terrace | AB3: 2300 | AC3: 2300 | AD3: =IFERROR(AB3/B3,"") -> 4.5544554 | AE3: =IFERROR(AC3/B3,"") -> 4.5544554 | AF3: No | AG3: No | AH3: Yes | AI3: 2026-06-17 | AJ3: C13423108 | AK3: https://condos.ca/toronto/concord-canada-house-23-spadina-ave-1-3-concord-cityplace-way/unit-4302-C13423108 | AL3: condos.ca registered area 505 sqft* (source Calculated), in MLS bracket 500-599; leased 2026-06-17. | AM3: Condo | AN3: =IFERROR(E3*(1+IF(AM3="Apartment",Data_Summary!$C$3,0)),"") -> 4.5544554 | AO3: 46195
A4: =IF(AND(ISNUMBER(B4),B4>0,ISNUMBER(AB4),AB4>0,J4>=Data_Summary!$C$1),1,0) -> 1 | B4: 722 | C4: =IF(ISNUMBER(AB4),AB4,"") -> 3000 | D4: =IF(ISNUMBER(C4),C4-U4*Data_Summary!$C$2,"") -> 3000 | E4: =IFERROR(C4/B4,"") -> 4.1551247 | F4: =IFERROR(D4/B4,"") -> 4.1551247 | G4: =Q4 -> 2 | H4: =IFERROR(LEFT(G4,1),"") -> 2 | I4: =IF(LEN(G4)>1,1,0) -> 0 | J4: 46185 | K4: Concord Canada House | L4: 23 Spadina Ave | M4: Toronto | N4: Concord Adex | O4: 633 | Q4: 2 | R4: 2 | S4: 722 | T4: 700-799 sqft | U4: 0 | V4: Yes | W4: None | X4: Balcony, Patio | Y4: N | Z4: Built 2025 (1 yrs) | AA4: Concierge, Gym, Party Room, Outdoor Terrace | AB4: 3000 | AC4: 3000 | AD4: =IFERROR(AB4/B4,"") -> 4.1551247 | AE4: =IFERROR(AC4/B4,"") -> 4.1551247 | AF4: No | AG4: No | AH4: Yes | AI4: 2026-06-12 | AJ4: C13418138 | AK4: https://condos.ca/toronto/concord-canada-house-23-spadina-ave-1-3-concord-cityplace-way/unit-633-C13418138 | AL4: condos.ca registered area 722 sqft* (source Calculated), in MLS bracket 700-799; leased 2026-06-12. | AM4: Condo | AN4: =IFERROR(E4*(1+IF(AM4="Apartment",Data_Summary!$C$3,0)),"") -> 4.1551247 | AO4: 46195
A5: =IF(AND(ISNUMBER(B5),B5>0,ISNUMBER(AB5),AB5>0,J5>=Data_Summary!$C$1),1,0) -> 1 | B5: 908 | C5: =IF(ISNUMBER(AB5),AB5,"") -> 4300 | D5: =IF(ISNUMBER(C5),C5-U5*Data_Summary!$C$2,"") -> 4150 | E5: =IFERROR(C5/B5,"") -> 4.7356828 | F5: =IFERROR(D5/B5,"") -> 4.5704846 | G5: =Q5 -> 3 | H5: =IFERROR(LEFT(G5,1),"") -> 3 | I5: =IF(LEN(G5)>1,1,0) -> 0 | J5: 46185 | K5: Concord Canada House | L5: 23 Spadina Ave | M5: Toronto | N5: Concord Adex | O5: 2505 | Q5: 3 | R5: 2 | S5: 908 | T5: 900-999 sqft | U5: 1 | V5: Yes | W5: None | X5: Balcony, Patio | Y5: SE | Z5: Built 2025 (1 yrs) | AA5: Concierge, Gym, Party Room, Outdoor Terrace | AB5: 4300 | AC5: 4300 | AD5: =IFERROR(AB5/B5,"") -> 4.7356828 | AE5: =IFERROR(AC5/B5,"") -> 4.7356828 | AF5: No | AG5: No | AH5: Yes | AI5: 2026-06-12 | AJ5: C13234234 | AK5: https://condos.ca/toronto/concord-canada-house-23-spadina-ave-1-3-concord-cityplace-way/unit-2505-C13234234 | AL5: condos.ca registered area 908 sqft* (source Calculated), in MLS bracket 900-999; leased 2026-06-12. | AM5: Condo | AN5: =IFERROR(E5*(1+IF(AM5="Apartment",Data_Summary!$C$3,0)),"") -> 4.7356828 | AO5: 46195
A6: =IF(AND(ISNUMBER(B6),B6>0,ISNUMBER(AB6),AB6>0,J6>=Data_Summary!$C$1),1,0) -> 1 | B6: 1050 | C6: =IF(ISNUMBER(AB6),AB6,"") -> 4500 | D6: =IF(ISNUMBER(C6),C6-U6*Data_Summary!$C$2,"") -> 4350 | E6: =IFERROR(C6/B6,"") -> 4.2857143 | F6: =IFERROR(D6/B6,"") -> 4.1428571 | G6: =Q6 -> 2 | H6: =IFERROR(LEFT(G6,1),"") -> 2 | I6: =IF(LEN(G6)>1,1,0) -> 0 | J6: 46185 | K6: Concord Canada House | L6: 23 Spadina Ave | M6: Toronto | N6: Concord Adex | O6: 6201 | Q6: 2 | R6: 3 | S6: 1050 | T6: 1000-1199 sqft | U6: 1 | V6: Yes | W6: None | X6: Balcony, Patio | Y6: W | Z6: Built 2025 (1 yrs) | AA6: Concierge, Gym, Party Room, Outdoor Terrace | AB6: 4500 | AC6: 4900 | AD6: =IFERROR(AB6/B6,"") -> 4.2857143 | AE6: =IFERROR(AC6/B6,"") -> 4.6666667 | AF6: No | AG6: No | AH6: Yes | AI6: 2026-06-12 | AJ6: C12939248 | AK6: https://condos.ca/toronto/concord-canada-house-23-spadina-ave-1-3-concord-cityplace-way/unit-6201-C12939248 | AL6: condos.ca registered area 1050 sqft* (source Calculated), in MLS bracket 1000-1199; leased 2026-06-12. | AM6: Condo | AN6: =IFERROR(E6*(1+IF(AM6="Apartment",Data_Summary!$C$3,0)),"") -> 4.2857143 | AO6: 46195
A7: =IF(AND(ISNUMBER(B7),B7>0,ISNUMBER(AB7),AB7>0,J7>=Data_Summary!$C$1),1,0) -> 1 | B7: 650 | C7: =IF(ISNUMBER(AB7),AB7,"") -> 2750 | D7: =IF(ISNUMBER(C7),C7-U7*Data_Summary!$C$2,"") -> 2750 | E7: =IFERROR(C7/B7,"") -> 4.2307692 | F7: =IFERROR(D7/B7,"") -> 4.2307692 | G7: =Q7 -> 1+1 | H7: =IFERROR(LEFT(G7,1),"") -> 1 | I7: =IF(LEN(G7)>1,1,0) -> 1 | J7: 46183 | K7: Concord Canada House | L7: 23 Spadina Ave | M7: Toronto | N7: Concord Adex | O7: 2106 | Q7: 1+1 | R7: 2 | S7: 650 | T7: 600-699 sqft | U7: 0 | V7: Yes | W7: None | X7: Balcony, Patio | Y7: E | Z7: Built 2025 (1 yrs) | AA7: Concierge, Gym, Party Room, Outdoor Terrace | AB7: 2750 | AC7: 2850 | AD7: =IFERROR(AB7/B7,"") -> 4.2307692 | AE7: =IFERROR(AC7/B7,"") -> 4.3846154 | AF7: No | AG7: No | AH7: No | AI7: 2026-06-10 | AJ7: C13217872 | AK7: https://condos.ca/toronto/concord-canada-house-23-spadina-ave-1-3-concord-cityplace-way/unit-2106-C13217872 | AL7: condos.ca registered area 650 sqft* (source Calculated), in MLS bracket 600-699; leased 2026-06-10. | AM7: Condo | AN7: =IFERROR(E7*(1+IF(AM7="Apartment",Data_Summary!$C$3,0)),"") -> 4.2307692 | AO7: 46195
A8: =IF(AND(ISNUMBER(B8),B8>0,ISNUMBER(AB8),AB8>0,J8>=Data_Summary!$C$1),1,0) -> 1 | B8: 736 | C8: =IF(ISNUMBER(AB8),AB8,"") -> 3050 | D8: =IF(ISNUMBER(C8),C8-U8*Data_Summary!$C$2,"") -> 3050 | E8: =IFERROR(C8/B8,"") -> 4.1440217 | F8: =IFERROR(D8/B8,"") -> 4.1440217 | G8: =Q8 -> 2 | H8: =IFERROR(LEFT(G8,1),"") -> 2 | I8: =IF(LEN(G8)>1,1,0) -> 0 | J8: 46182 | K8: Concord Canada House | L8: 23 Spadina Ave | M8: Toronto | N8: Concord Adex | O8: 312 | Q8: 2 | R8: 2 | S8: 736 | T8: 700-799 sqft | U8: 0 | V8: Yes | W8: None | X8: Balcony, Patio | Y8: S | Z8: Built 2025 (1 yrs) | AA8: Concierge, Gym, Party Room, Outdoor Terrace | AB8: 3050 | AC8: 3150 | AD8: =IFERROR(AB8/B8,"") -> 4.1440217 | AE8: =IFERROR(AC8/B8,"") -> 4.2798913 | AF8: No | AG8: No | AH8: Yes | AI8: 2026-06-09 | AJ8: C13157296 | AK8: https://condos.ca/toronto/concord-canada-house-23-spadina-ave-1-3-concord-cityplace-way/unit-312-C13157296 | AL8: condos.ca registered area 736 sqft* (source Calculated), in MLS bracket 700-799; leased 2026-06-09. | AM8: Condo | AN8: =IFERROR(E8*(1+IF(AM8="Apartment",Data_Summary!$C$3,0)),"") -> 4.1440217 | AO8: 46195
A9: =IF(AND(ISNUMBER(B9),B9>0,ISNUMBER(AB9),AB9>0,J9>=Data_Summary!$C$1),1,0) -> 1 | B9: 540 | C9: =IF(ISNUMBER(AB9),AB9,"") -> 4000 | D9: =IF(ISNUMBER(C9),C9-U9*Data_Summary!$C$2,"") -> 4000 | E9: =IFERROR(C9/B9,"") -> 7.4074074 | F9: =IFERROR(D9/B9,"") -> 7.4074074 | G9: =Q9 -> 1 | H9: =IFERROR(LEFT(G9,1),"") -> 1 | I9: =IF(LEN(G9)>1,1,0) -> 0 | J9: 46182 | K9: Concord Canada House | L9: 23 Spadina Ave | M9: Toronto | N9: Concord Adex | O9: 3308 | Q9: 1 | R9: 1 | S9: 540 | T9: 500-599 sqft | U9: 0 | V9: Yes | W9: None | X9: Balcony, Patio | Y9: S | Z9: Built 2025 (1 yrs) | AA9: Concierge, Gym, Party Room, Outdoor Terrace | AB9: 4000 | AC9: 3800 | AD9: =IFERROR(AB9/B9,"") -> 7.4074074 | AE9: =IFERROR(AC9/B9,"") -> 7.037037 | AF9: Yes | AG9: No | AH9: Yes | AI9: 2026-06-09 | AJ9: C13075812 | AK9: https://condos.ca/toronto/concord-canada-house-23-spadina-ave-1-3-concord-cityplace-way/unit-3308-C13075812 | AL9: condos.ca area 540 sqft*; furnished/short-term lease; leased 2026-06-09. | AM9: Condo | AN9: =IFERROR(E9*(1+IF(AM9="Apartment",Data_Summary!$C$3,0)),"") -> 7.4074074 | AO9: 46195
A10: =IF(AND(ISNUMBER(B10),B10>0,ISNUMBER(AB10),AB10>0,J10>=Data_Summary!$C$1),1,0) -> 1 | B10: 600 | C10: =IF(ISNUMBER(AB10),AB10,"") -> 2800 | D10: =IF(ISNUMBER(C10),C10-U10*Data_Summary!$C$2,"") -> 2800 | E10: =IFERROR(C10/B10,"") -> 4.6666667 | F10: =IFERROR(D10/B10,"") -> 4.6666667 | G10: =Q10 -> 1+1 | H10: =IFERROR(LEFT(G10,1),"") -> 1 | I10: =IF(LEN(G10)>1,1,0) -> 1 | J10: 46182 | K10: Concord Canada House | L10: 23 Spadina Ave | M10: Toronto | N10: Concord Adex | O10: 2608 | Q10: 1+1 | R10: 1 | S10: 600 | T10: 600-699 sqft | U10: 0 | V10: Yes | W10: None | X10: Balcony, Patio | Y10: E | Z10: Built 2025 (1 yrs) | AA10: Concierge, Gym, Party Room, Outdoor Terrace | AB10: 2800 | AC10: 2850 | AD10: =IFERROR(AB10/B10,"") -> 4.6666667 | AE10: =IFERROR(AC10/B10,"") -> 4.75 | AF10: Yes | AG10: No | AH10: Yes | AI10: 2026-06-09 | AJ10: C12874476 | AK10: https://condos.ca/toronto/concord-canada-house-23-spadina-ave-1-3-concord-cityplace-way/unit-2608-C12874476 | AL10: condos.ca area 600 sqft*; furnished/short-term lease; leased 2026-06-09. | AM10: Condo | AN10: =IFERROR(E10*(1+IF(AM10="Apartment",Data_Summary!$C$3,0)),"") -> 4.6666667 | AO10: 46195
A11: =IF(AND(ISNUMBER(B11),B11>0,ISNUMBER(AB11),AB11>0,J11>=Data_Summary!$C$1),1,0) -> 1 | B11: 718 | C11: =IF(ISNUMBER(AB11),AB11,"") -> 3500 | D11: =IF(ISNUMBER(C11),C11-U11*Data_Summary!$C$2,"") -> 3350 | E11: =IFERROR(C11/B11,"") -> 4.8746518 | F11: =IFERROR(D11/B11,"") -> 4.6657382 | G11: =Q11 -> 2 | H11: =IFERROR(LEFT(G11,1),"") -> 2 | I11: =IF(LEN(G11)>1,1,0) -> 0 | J11: 46181 | K11: Concord Canada House | L11: 23 Spadina Ave | M11: Toronto | N11: Concord Adex | O11: 5611 | Q11: 2 | R11: 2 | S11: 718 | T11: 700-799 sqft | U11: 1 | V11: Yes | W11: Owned | X11: Balcony, Patio | Y11: NW | Z11: Built 2025 (1 yrs) | AA11: Concierge, Gym, Party Room, Outdoor Terrace | AB11: 3500 | AC11: 3400 | AD11: =IFERROR(AB11/B11,"") -> 4.8746518 | AE11: =IFERROR(AC11/B11,"") -> 4.735376 | AF11: No | AG11: No | AH11: Yes | AI11: 2026-06-08 | AJ11: C13238978 | AK11: https://condos.ca/toronto/concord-canada-house-23-spadina-ave-1-3-concord-cityplace-way/unit-5611-C13238978 | AL11: condos.ca registered area 718 sqft* (source Calculated), in MLS bracket 700-799; leased 2026-06-08. | AM11: Condo | AN11: =IFERROR(E11*(1+IF(AM11="Apartment",Data_Summary!$C$3,0)),"") -> 4.8746518 | AO11: 46195
A12: =IF(AND(ISNUMBER(B12),B12>0,ISNUMBER(AB12),AB12>0,J12>=Data_Summary!$C$1),1,0) -> 1 | B12: 578 | C12: =IF(ISNUMBER(AB12),AB12,"") -> 2500 | D12: =IF(ISNUMBER(C12),C12-U12*Data_Summary!$C$2,"") -> 2500 | E12: =IFERROR(C12/B12,"") -> 4.3252595 | F12: =IFERROR(D12/B12,"") -> 4.3252595 | G12: =Q12 -> 1 | H12: =IFERROR(LEFT(G12,1),"") -> 1 | I12: =IF(LEN(G12)>1,1,0) -> 0 | J12: 46178 | K12: Concord Canada House | L12: 23 Spadina Ave | M12: Toronto | N12: Concord Adex | O12: 1907 | Q12: 1 | R12: 1 | S12: 578 | T12: 700-799 sqft | U12: 0 | V12: Yes | W12: None | X12: Balcony, Patio | Y12: SW | Z12: Built 2025 (1 yrs) | AA12: Concierge, Gym, Party Room, Outdoor Terrace | AB12: 2500 | AC12: 2500 | AD12: =IFERROR(AB12/B12,"") -> 4.3252595 | AE12: =IFERROR(AC12/B12,"") -> 4.3252595 | AF12: No | AG12: No | AH12: No | AI12: 2026-06-05 | AJ12: C13219416 | AK12: https://condos.ca/toronto/concord-canada-house-23-spadina-ave-1-3-concord-cityplace-way/unit-1907-C13219416 | AL12: condos.ca area 578 sqft*; calc SF 578 outside MLS bracket 700-799 — flagged; leased 2026-06-05. | AM12: Condo | AN12: =IFERROR(E12*(1+IF(AM12="Apartment",Data_Summary!$C$3,0)),"") -> 4.3252595 | AO12: 46195
A13: =IF(AND(ISNUMBER(B13),B13>0,ISNUMBER(AB13),AB13>0,J13>=Data_Summary!$C$1),1,0) -> 1 | B13: 485 | C13: =IF(ISNUMBER(AB13),AB13,"") -> 2300 | D13: =IF(ISNUMBER(C13),C13-U13*Data_Summary!$C$2,"") -> 2300 | E13: =IFERROR(C13/B13,"") -> 4.742268 | F13: =IFERROR(D13/B13,"") -> 4.742268 | G13: =Q13 -> 1 | H13: =IFERROR(LEFT(G13,1),"") -> 1 | I13: =IF(LEN(G13)>1,1,0) -> 0 | J13: 46178 | K13: Concord Canada House | L13: 23 Spadina Ave | M13: Toronto | N13: Concord Adex | O13: 1715 | Q13: 1 | R13: 1 | S13: 485 | T13: 0-499 sqft | U13: 0 | V13: Yes | W13: Owned | X13: Balcony, Patio | Y13: N | Z13: Built 2025 (1 yrs) | AA13: Concierge, Gym, Party Room, Outdoor Terrace | AB13: 2300 | AC13: 2250 | AD13: =IFERROR(AB13/B13,"") -> 4.742268 | AE13: =IFERROR(AC13/B13,"") -> 4.6391753 | AF13: No | AG13: No | AH13: No | AI13: 2026-06-05 | AJ13: C13186274 | AK13: https://condos.ca/toronto/concord-canada-house-23-spadina-ave-1-3-concord-cityplace-way/unit-1715-C13186274 | AL13: condos.ca registered area 485 sqft* (source Calculated), in MLS bracket 0-499; leased 2026-06-05. | AM13: Condo | AN13: =IFERROR(E13*(1+IF(AM13="Apartment",Data_Summary!$C$3,0)),"") -> 4.742268 | AO13: 46195
... A285: =IF(AND(ISNUMBER(B285),B285>0,ISNUMBER(AB285),AB285>0,J285>=Data_Summary!$C$1),1,0) -> 1 | B285: 535 | C285: =IF(ISNUMBER(AB285),AB285,"") -> 2500 | D285: =IF(ISNUMBER(C285),C285-U285*Data_Summary!$C$2,"") -> 2500 | E285: =IFERROR(C285/B285,"") -> 4.6728972 | F285: =IFERROR(D285/B285,"") -> 4.6728972 | G285: =Q285 -> 1+1 | H285: =IFERROR(LEFT(G285,1),"") -> 1 | I285: =IF(LEN(G285)>1,1,0) -> 1 | J285: 45794 | K285: Concord Canada House | L285: 23 Spadina Ave | M285: Toronto | N285: Concord Adex | O285: 2009 | Q285: 1+1 | R285: 2 | S285: 535 | T285: 600-699 sqft | U285: 0 | V285: Yes | W285: None | X285: Balcony, Patio | Y285: S | Z285: Built 2025 (1 yrs) | AA285: Concierge, Gym, Party Room, Outdoor Terrace | AB285: 2500 | AC285: 2500 | AD285: =IFERROR(AB285/B285,"") -> 4.6728972 | AE285: =IFERROR(AC285/B285,"") -> 4.6728972 | AF285: No | AG285: No | AH285: Yes | AI285: 2025-05-17 | AJ285: C12156057 | AK285: https://condos.ca/toronto/concord-canada-house-23-spadina-ave-1-3-concord-cityplace-way/unit-2009-C12156057 | AL285: condos.ca area 535 sqft*; calc SF 535 outside MLS bracket 600-699 — flagged; leased 2025-05-17. | AM285: Condo | AN285: =IFERROR(E285*(1+IF(AM285="Apartment",Data_Summary!$C$3,0)),"") -> 4.6728972 | AO285: 46195
A286: =IF(AND(ISNUMBER(B286),B286>0,ISNUMBER(AB286),AB286>0,J286>=Data_Summary!$C$1),1,0) -> 1 | B286: 594 | C286: =IF(ISNUMBER(AB286),AB286,"") -> 2350 | D286: =IF(ISNUMBER(C286),C286-U286*Data_Summary!$C$2,"") -> 2350 | E286: =IFERROR(C286/B286,"") -> 3.956229 | F286: =IFERROR(D286/B286,"") -> 3.956229 | G286: =Q286 -> 1+1 | H286: =IFERROR(LEFT(G286,1),"") -> 1 | I286: =IF(LEN(G286)>1,1,0) -> 1 | J286: 46189 | K286: Nobu Residences | L286: 15 Mercer St | M286: Toronto | N286: Madison Group | O286: 405 | Q286: 1+1 | R286: 2 | S286: 594 | T286: 500-599 sqft | U286: 0 | V286: Yes | W286: None | Y286: S | Z286: Built 2024 (2 yrs) | AA286: Concierge, Gym, Party Room, Outdoor Terrace | AB286: 2350 | AC286: 2395 | AD286: =IFERROR(AB286/B286,"") -> 3.956229 | AE286: =IFERROR(AC286/B286,"") -> 4.0319865 | AF286: No | AG286: No | AH286: No | AI286: 2026-06-16 | AJ286: C13092264 | AK286: https://condos.ca/toronto/nobu-residences-15-mercer-st-35-mercer-st/unit-405-C13092264 | AL286: condos.ca registered area 594 sqft* (source Calculated), in MLS bracket 500-599; leased 2026-06-16. | AM286: Condo | AN286: =IFERROR(E286*(1+IF(AM286="Apartment",Data_Summary!$C$3,0)),"") -> 3.956229 | AO286: 46195
A287: =IF(AND(ISNUMBER(B287),B287>0,ISNUMBER(AB287),AB287>0,J287>=Data_Summary!$C$1),1,0) -> 1 | B287: 929 | C287: =IF(ISNUMBER(AB287),AB287,"") -> 3990 | D287: =IF(ISNUMBER(C287),C287-U287*Data_Summary!$C$2,"") -> 3840 | E287: =IFERROR(C287/B287,"") -> 4.2949408 | F287: =IFERROR(D287/B287,"") -> 4.1334769 | G287: =Q287 -> 3+1 | H287: =IFERROR(LEFT(G287,1),"") -> 3 | I287: =IF(LEN(G287)>1,1,0) -> 1 | J287: 46188 | K287: Nobu Residences | L287: 15 Mercer St | M287: Toronto | N287: Madison Group | O287: 2504 | Q287: 3+1 | R287: 2 | S287: 929 | T287: 900-999 sqft | U287: 1 | V287: Yes | W287: None | X287: Balcony, Patio | Y287: NE | Z287: Built 2024 (2 yrs) | AA287: Concierge, Gym, Party Room, Outdoor Terrace | AB287: 3990 | AC287: 3990 | AD287: =IFERROR(AB287/B287,"") -> 4.2949408 | AE287: =IFERROR(AC287/B287,"") -> 4.2949408 | AF287: No | AG287: No | AH287: No | AI287: 2026-06-15 | AJ287: C12881654 | AK287: https://condos.ca/toronto/nobu-residences-15-mercer-st-35-mercer-st/unit-2504-C12881654 | AL287: condos.ca registered area 929 sqft* (source Calculated), in MLS bracket 900-999; leased 2026-06-15. | AM287: Condo | AN287: =IFERROR(E287*(1+IF(AM287="Apartment",Data_Summary!$C$3,0)),"") -> 4.2949408 | AO287: 46195
A288: =IF(AND(ISNUMBER(B288),B288>0,ISNUMBER(AB288),AB288>0,J288>=Data_Summary!$C$1),1,0) -> 1 | B288: 649 | C288: =IF(ISNUMBER(AB288),AB288,"") -> 2950 | D288: =IF(ISNUMBER(C288),C288-U288*Data_Summary!$C$2,"") -> 2950 | E288: =IFERROR(C288/B288,"") -> 4.5454545 | F288: =IFERROR(D288/B288,"") -> 4.5454545 | G288: =Q288 -> 2 | H288: =IFERROR(LEFT(G288,1),"") -> 2 | I288: =IF(LEN(G288)>1,1,0) -> 0 | J288: 46186 | K288: Nobu Residences | L288: 15 Mercer St | M288: Toronto | N288: Madison Group | O288: 818 | Q288: 2 | R288: 2 | S288: 649 | T288: 600-699 sqft | U288: 0 | V288: Yes | W288: None | Y288: N | Z288: Built 2024 (2 yrs) | AA288: Concierge, Gym, Party Room, Outdoor Terrace | AB288: 2950 | AC288: 2950 | AD288: =IFERROR(AB288/B288,"") -> 4.5454545 | AE288: =IFERROR(AC288/B288,"") -> 4.5454545 | AF288: No | AG288: No | AH288: No | AI288: 2026-06-13 | AJ288: C13117738 | AK288: https://condos.ca/toronto/nobu-residences-15-mercer-st-35-mercer-st/unit-818-C13117738 | AL288: condos.ca registered area 649 sqft* (source Calculated), in MLS bracket 600-699; leased 2026-06-13. | AM288: Condo | AN288: =IFERROR(E288*(1+IF(AM288="Apartment",Data_Summary!$C$3,0)),"") -> 4.5454545 | AO288: 46195
A289: =IF(AND(ISNUMBER(B289),B289>0,ISNUMBER(AB289),AB289>0,J289>=Data_Summary!$C$1),1,0) -> 1 | B289: 799 | C289: =IF(ISNUMBER(AB289),AB289,"") -> 3395 | D289: =IF(ISNUMBER(C289),C289-U289*Data_Summary!$C$2,"") -> 3395 | E289: =IFERROR(C289/B289,"") -> 4.2490613 | F289: =IFERROR(D289/B289,"") -> 4.2490613 | G289: =Q289 -> 2 | H289: =IFERROR(LEFT(G289,1),"") -> 2 | I289: =IF(LEN(G289)>1,1,0) -> 0 | J289: 46181 | K289: Nobu Residences | L289: 15 Mercer St | M289: Toronto | N289: Madison Group | O289: 3910 | Q289: 2 | R289: 2 | S289: 799 | T289: 700-799 sqft | U289: 0 | V289: Yes | W289: None | X289: Balcony, Patio | Y289: NW | Z289: Built 2024 (2 yrs) | AA289: Concierge, Gym, Party Room, Outdoor Terrace | AB289: 3395 | AC289: 3395 | AD289: =IFERROR(AB289/B289,"") -> 4.2490613 | AE289: =IFERROR(AC289/B289,"") -> 4.2490613 | AF289: No | AG289: No | AH289: No | AI289: 2026-06-08 | AJ289: C13222970 | AK289: https://condos.ca/toronto/nobu-residences-15-mercer-st-35-mercer-st/unit-3910-C13222970 | AL289: condos.ca registered area 799 sqft* (source Calculated), in MLS bracket 700-799; leased 2026-06-08. | AM289: Condo | AN289: =IFERROR(E289*(1+IF(AM289="Apartment",Data_Summary!$C$3,0)),"") -> 4.2490613 | AO289: 46195
A290: =IF(AND(ISNUMBER(B290),B290>0,ISNUMBER(AB290),AB290>0,J290>=Data_Summary!$C$1),1,0) -> 1 | B290: 416 | C290: =IF(ISNUMBER(AB290),AB290,"") -> 2150 | D290: =IF(ISNUMBER(C290),C290-U290*Data_Summary!$C$2,"") -> 2150 | E290: =IFERROR(C290/B290,"") -> 5.1682692 | F290: =IFERROR(D290/B290,"") -> 5.1682692 | G290: =Q290 -> 1 | H290: =IFERROR(LEFT(G290,1),"") -> 1 | I290: =IF(LEN(G290)>1,1,0) -> 0 | J290: 46180 | K290: Nobu Residences | L290: 15 Mercer St | M290: Toronto | N290: Madison Group | O290: 1103 | Q290: 1 | R290: 1 | S290: 416 | T290: 0-499 sqft | U290: 0 | V290: Yes | W290: None | Y290: W | Z290: Built 2024 (2 yrs) | AA290: Concierge, Gym, Party Room, Outdoor Terrace | AB290: 2150 | AC290: 2150 | AD290: =IFERROR(AB290/B290,"") -> 5.1682692 | AE290: =IFERROR(AC290/B290,"") -> 5.1682692 | AF290: No | AG290: No | AH290: No | AI290: 2026-06-07 | AJ290: C13049560 | AK290: https://condos.ca/toronto/nobu-residences-15-mercer-st-35-mercer-st/unit-1103-C13049560 | AL290: condos.ca registered area 416 sqft* (source Calculated), in MLS bracket 0-499; leased 2026-06-07. | AM290: Condo | AN290: =IFERROR(E290*(1+IF(AM290="Apartment",Data_Summary!$C$3,0)),"") -> 5.1682692 | AO290: 46195
A291: =IF(AND(ISNUMBER(B291),B291>0,ISNUMBER(AB291),AB291>0,J291>=Data_Summary!$C$1),1,0) -> 1 | B291: 799 | C291: =IF(ISNUMBER(AB291),AB291,"") -> 3300 | D291: =IF(ISNUMBER(C291),C291-U291*Data_Summary!$C$2,"") -> 3300 | E291: =IFERROR(C291/B291,"") -> 4.1301627 | F291: =IFERROR(D291/B291,"") -> 4.1301627 | G291: =Q291 -> 2+1 | H291: =IFERROR(LEFT(G291,1),"") -> 2 | I291: =IF(LEN(G291)>1,1,0) -> 1 | J291: 46178 | K291: Nobu Residences | L291: 15 Mercer St | M291: Toronto | N291: Madison Group | O291: 1706 | Q291: 2+1 | R291: 2 | S291: 799 | T291: 700-799 sqft | U291: 0 | V291: Yes | W291: None | X291: Balcony, Patio | Y291: NE | Z291: Built 2024 (2 yrs) | AA291: Concierge, Gym, Party Room, Outdoor Terrace | AB291: 3300 | AC291: 3550 | AD291: =IFERROR(AB291/B291,"") -> 4.1301627 | AE291: =IFERROR(AC291/B291,"") -> 4.4430538 | AF291: No | AG291: No | AH291: No | AI291: 2026-06-05 | AJ291: C13106892 | AK291: https://condos.ca/toronto/nobu-residences-15-mercer-st-35-mercer-st/unit-1706-C13106892 | AL291: condos.ca registered area 799 sqft* (source Calculated), in MLS bracket 700-799; leased 2026-06-05. | AM291: Condo | AN291: =IFERROR(E291*(1+IF(AM291="Apartment",Data_Summary!$C$3,0)),"") -> 4.1301627 | AO291: 46195
A292: =IF(AND(ISNUMBER(B292),B292>0,ISNUMBER(AB292),AB292>0,J292>=Data_Summary!$C$1),1,0) -> 1 | B292: 625 | C292: =IF(ISNUMBER(AB292),AB292,"") -> 2625 | D292: =IF(ISNUMBER(C292),C292-U292*Data_Summary!$C$2,"") -> 2625 | E292: =IFERROR(C292/B292,"") -> 4.2 | F292: =IFERROR(D292/B292,"") -> 4.2 | G292: =Q292 -> 2 | H292: =IFERROR(LEFT(G292,1),"") -> 2 | I292: =IF(LEN(G292)>1,1,0) -> 0 | J292: 46177 | K292: Nobu Residences | L292: 15 Mercer St | M292: Toronto | N292: Madison Group | O292: 702 | Q292: 2 | R292: 2 | S292: 625 | T292: 700-799 sqft | U292: 0 | V292: Yes | W292: None | Y292: S | Z292: Built 2024 (2 yrs) | AA292: Concierge, Gym, Party Room, Outdoor Terrace | AB292: 2625 | AC292: 2625 | AD292: =IFERROR(AB292/B292,"") -> 4.2 | AE292: =IFERROR(AC292/B292,"") -> 4.2 | AF292: No | AG292: No | AH292: No | AI292: 2026-06-04 | AJ292: C13149188 | AK292: https://condos.ca/toronto/nobu-residences-15-mercer-st-35-mercer-st/unit-702-C13149188 | AL292: condos.ca area 625 sqft*; calc SF 625 outside MLS bracket 700-799 — flagged; leased 2026-06-04. | AM292: Condo | AN292: =IFERROR(E292*(1+IF(AM292="Apartment",Data_Summary!$C$3,0)),"") -> 4.2 | AO292: 46195
A293: =IF(AND(ISNUMBER(B293),B293>0,ISNUMBER(AB293),AB293>0,J293>=Data_Summary!$C$1),1,0) -> 1 | B293: 427 | C293: =IF(ISNUMBER(AB293),AB293,"") -> 2200 | D293: =IF(ISNUMBER(C293),C293-U293*Data_Summary!$C$2,"") -> 2200 | E293: =IFERROR(C293/B293,"") -> 5.1522248 | F293: =IFERROR(D293/B293,"") -> 5.1522248 | G293: =Q293 -> 1 | H293: =IFERROR(LEFT(G293,1),"") -> 1 | I293: =IF(LEN(G293)>1,1,0) -> 0 | J293: 46177 | K293: Nobu Residences | L293: 15 Mercer St | M293: Toronto | N293: Madison Group | O293: 1603 | Q293: 1 | R293: 1 | S293: 427 | T293: 0-499 sqft | U293: 0 | V293: Yes | W293: None | Y293: W | Z293: Built 2024 (2 yrs) | AA293: Concierge, Gym, Party Room, Outdoor Terrace | AB293: 2200 | AC293: 2200 | AD293: =IFERROR(AB293/B293,"") -> 5.1522248 | AE293: =IFERROR(AC293/B293,"") -> 5.1522248 | AF293: No | AG293: No | AH293: No | AI293: 2026-06-04 | AJ293: C13110904 | AK293: https://condos.ca/toronto/nobu-residences-15-mercer-st-35-mercer-st/unit-1603-C13110904 | AL293: condos.ca area 427 sqft*; size 'Known'/stated (not registered area); leased 2026-06-04. | AM293: Condo | AN293: =IFERROR(E293*(1+IF(AM293="Apartment",Data_Summary!$C$3,0)),"") -> 5.1522248 | AO293: 46195
A294: =IF(AND(ISNUMBER(B294),B294>0,ISNUMBER(AB294),AB294>0,J294>=Data_Summary!$C$1),1,0) -> 1 | B294: 667 | C294: =IF(ISNUMBER(AB294),AB294,"") -> 3000 | D294: =IF(ISNUMBER(C294),C294-U294*Data_Summary!$C$2,"") -> 3000 | E294: =IFERROR(C294/B294,"") -> 4.4977511 | F294: =IFERROR(D294/B294,"") -> 4.4977511 | G294: =Q294 -> 2 | H294: =IFERROR(LEFT(G294,1),"") -> 2 | I294: =IF(LEN(G294)>1,1,0) -> 0 | J294: 46172 | K294: Nobu Residences | L294: 15 Mercer St | M294: Toronto | N294: Madison Group | O294: 2316 | Q294: 2 | R294: 2 | S294: 667 | T294: 600-699 sqft | U294: 0 | V294: Yes | W294: None | Y294: S | Z294: Built 2024 (2 yrs) | AA294: Concierge, Gym, Party Room, Outdoor Terrace | AB294: 3000 | AC294: 3000 | AD294: =IFERROR(AB294/B294,"") -> 4.4977511 | AE294: =IFERROR(AC294/B294,"") -> 4.4977511 | AF294: No | AG294: No | AH294: No | AI294: 2026-05-30 | AJ294: C13209116 | AK294: https://condos.ca/toronto/nobu-residences-15-mercer-st-35-mercer-st/unit-2316-C13209116 | AL294: condos.ca registered area 667 sqft* (source Calculated), in MLS bracket 600-699; leased 2026-05-30. | AM294: Condo | AN294: =IFERROR(E294*(1+IF(AM294="Apartment",Data_Summary!$C$3,0)),"") -> 4.4977511 | AO294: 46195
A295: =IF(AND(ISNUMBER(B295),B295>0,ISNUMBER(AB295),AB295>0,J295>=Data_Summary!$C$1),1,0) -> 1 | B295: 814 | C295: =IF(ISNUMBER(AB295),AB295,"") -> 3000 | D295: =IF(ISNUMBER(C295),C295-U295*Data_Summary!$C$2,"") -> 3000 | E295: =IFERROR(C295/B295,"") -> 3.6855037 | F295: =IFERROR(D295/B295,"") -> 3.6855037 | G295: =Q295 -> 2+1 | H295: =IFERROR(LEFT(G295,1),"") -> 2 | I295: =IF(LEN(G295)>1,1,0) -> 1 | J295: 46171 | K295: Nobu Residences | L295: 15 Mercer St | M295: Toronto | N295: Madison Group | O295: 1904 | Q295: 2+1 | R295: 2 | S295: 814 | T295: 800-899 sqft | U295: 0 | V295: Yes | W295: None | Y295: N | Z295: Built 2024 (2 yrs) | AA295: Concierge, Gym, Party Room, Outdoor Terrace | AB295: 3000 | AC295: 3000 | AD295: =IFERROR(AB295/B295,"") -> 3.6855037 | AE295: =IFERROR(AC295/B295,"") -> 3.6855037 | AF295: No | AG295: No | AH295: No | AI295: 2026-05-29 | AJ295: C13091688 | AK295: https://condos.ca/toronto/nobu-residences-15-mercer-st-35-mercer-st/unit-1904-C13091688 | AL295: condos.ca registered area 814 sqft* (source Calculated), in MLS bracket 800-899; leased 2026-05-29. | AM295: Condo | AN295: =IFERROR(E295*(1+IF(AM295="Apartment",Data_Summary!$C$3,0)),"") -> 3.6855037 | AO295: 46195
A296: =IF(AND(ISNUMBER(B296),B296>0,ISNUMBER(AB296),AB296>0,J296>=Data_Summary!$C$1),1,0) -> 1 | B296: 692 | C296: =IF(ISNUMBER(AB296),AB296,"") -> 4000 | D296: =IF(ISNUMBER(C296),C296-U296*Data_Summary!$C$2,"") -> 4000 | E296: =IFERROR(C296/B296,"") -> 5.7803468 | F296: =IFERROR(D296/B296,"") -> 5.7803468 | G296: =Q296 -> 2 | H296: =IFERROR(LEFT(G296,1),"") -> 2 | I296: =IF(LEN(G296)>1,1,0) -> 0 | J296: 46170 | K296: Nobu Residences | L296: 15 Mercer St | M296: Toronto | N296: Madison Group | O296: 2013 | Q296: 2 | R296: 2 | S296: 692 | T296: 700-799 sqft | U296: 0 | V296: Yes | W296: None | Y296: N | Z296: Built 2024 (2 yrs) | AA296: Concierge, Gym, Party Room, Outdoor Terrace | AB296: 4000 | AC296: 3700 | AD296: =IFERROR(AB296/B296,"") -> 5.7803468 | AE296: =IFERROR(AC296/B296,"") -> 5.3468208 | AF296: Yes | AG296: No | AH296: No | AI296: 2026-05-28 | AJ296: C13130320 | AK296: https://condos.ca/toronto/nobu-residences-15-mercer-st-35-mercer-st/unit-2013-C13130320 | AL296: condos.ca area 692 sqft*; calc SF 692 outside MLS bracket 700-799 — flagged; furnished/short-term lease; leased 2026-05-28. | AM296: Condo | AN296: =IFERROR(E296*(1+IF(AM296="Apartment",Data_Summary!$C$3,0)),"") -> 5.7803468 | AO296: 46195
A297: =IF(AND(ISNUMBER(B297),B297>0,ISNUMBER(AB297),AB297>0,J297>=Data_Summary!$C$1),1,0) -> 1 | B297: 652 | C297: =IF(ISNUMBER(AB297),AB297,"") -> 3100 | D297: =IF(ISNUMBER(C297),C297-U297*Data_Summary!$C$2,"") -> 3100 | E297: =IFERROR(C297/B297,"") -> 4.7546012 | F297: =IFERROR(D297/B297,"") -> 4.7546012 | G297: =Q297 -> 2 | H297: =IFERROR(LEFT(G297,1),"") -> 2 | I297: =IF(LEN(G297)>1,1,0) -> 0 | J297: 46167 | K297: Nobu Residences | L297: 15 Mercer St | M297: Toronto | N297: Madison Group | O297: 3809 | Q297: 2 | R297: 2 | S297: 652 | T297: 600-699 sqft | U297: 0 | V297: Yes | W297: None | Y297: N | Z297: Built 2024 (2 yrs) | AA297: Concierge, Gym, Party Room, Outdoor Terrace | AB297: 3100 | AC297: 3000 | AD297: =IFERROR(AB297/B297,"") -> 4.7546012 | AE297: =IFERROR(AC297/B297,"") -> 4.601227 | AF297: No | AG297: No | AH297: No | AI297: 2026-05-25 | AJ297: C13032942 | AK297: https://condos.ca/toronto/nobu-residences-15-mercer-st-35-mercer-st/unit-3809-C13032942 | AL297: condos.ca registered area 652 sqft* (source Calculated), in MLS bracket 600-699; leased 2026-05-25. | AM297: Condo | AN297: =IFERROR(E297*(1+IF(AM297="Apartment",Data_Summary!$C$3,0)),"") -> 4.7546012 | AO297: 46195
